Workbook

Sheet Raw_Data
A1: Project_ID | B1: Client_ID | C1: Client_Name | D1: Project_Date | E1: Service | F1: Service_Category | G1: Industry | H1: Region | I1: Client_Type | J1: Project_Status | K1: Team_Size | L1: Project_Duration_Days | M1: Quoted_Value | N1: Discount | O1: Revenue | P1: Project_Cost | Q1: Profit | R1: Profit_Margin_Pct | S1: Lead_Source | T1: Marketing_Spend | U1: Customer_Rating | V1: Acquisition_Channel
A2: JSM10001 | B2: C0013 | C2: Client 0013 | D2: 2025-10-09 | E2: Social Media Marketing | F2: Social Media Marketing | G2: Education | H2: Ahmedabad | I2: Returning | J2: Completed | K2: 5 | L2: 46.0 | M2: 41100.0 | N2: 6200.0 | O2: 34900.0 | P2: 29300.0 | Q2: 5600.0 | R2: 16.05 | S2: Google | T2: 4300.0 | U2: 3.5 | V2: Organic Search
A3: JSM10002 | B3: C0112 | C3: Client 0112 | D3: 2025-08-27 | E3: SMM | F3: Social Media Marketing | G3: Manufacturing | H3: Pune | I3: Returning | J3: Completed | K3: 10 | L3: 35.0 | M3: 15000.0 | N3: 800.0 | O3: 14200.0 | P3: 7200.0 | Q3: 7000.0 | R3: 49.3 | S3: Direct | T3: 1000.0 | U3: 3.8 | V3: Direct
A4: JSM10003 | B4: C0415 | C4: Client 0415 | D4: 2025-01-07 | E4: content marketing | F4: Content Marketing | G4: Hospitality | H4: Bengaluru | I4: New | J4: Ongoing | K4: 4 | L4: 27.0 | M4: 33200.0 | N4: 3300.0 | O4: 29900.0 | P4: 16400.0 | Q4: 13500.0 | R4: 45.15 | S4: Referral | T4: 3800.0 | U4: 2.5 | V4: Social
A5: JSM10004 | B5: C0048 | C5: Client 0048 | D5: 2026-01-25 | E5: social media marketing | F5: Social Media Marketing | G5: Hospitality | H5: Mumbai | I5: Returning | J5: Completed | K5: 3 | L5: 48.0 | M5: 38600.0 | N5: 3900.0 | O5: 34700.0 | P5: 25800.0 | Q5: 8900.0 | R5: 25.65 | S5: Partner | T5: 3900.0 | U5: 4.0 | V5: Referral
A6: JSM10005 | B6: C0194 | C6: Client 0194 | D6: 2025-03-22 | E6: social media marketing | F6: Social Media Marketing | G6: Real Estate | H6: Delhi NCR | I6: New | J6: Completed | K6: 10 | L6: 28.0 | M6: 47100.0 | N6: 7100.0 | O6: 40000.0 | P6: 31200.0 | Q6: 8800.0 | R6: 22.0 | S6: Google | T6: 4100.0 | U6: 2.8 | V6: Paid Search
A7: JSM10006 | B7: C0041 | C7: Client 0041 | D7: 2025-08-27 | E7: content marketing | F7: Content Marketing | G7: Finance | H7: Bengaluru | I7: Returning | J7: Completed | K7: 3 | L7: 58.0 | M7: 68100.0 | N7: 3400.0 | O7: 64700.0 | P7: 45200.0 | Q7: 19500.0 | R7: 30.14 | S7: Social Media | T7: 10800.0 | U7: 3.4 | V7: Social
A8: JSM10007 | B8: C0344 | C8: Client 0344 | D8: 2025-10-01 | E8: Web Dev | F8: Web Development | G8: Real Estate | H8: Bengaluru | I8: New | J8: Completed | K8: 3 | L8: 52.0 | M8: 22700.0 | N8: 4500.0 | O8: 18200.0 | P8: 12400.0 | Q8: 5800.0 | R8: 31.87 | S8: Direct | T8: 1300.0 | U8: 3.8 | V8: Referral
A9: JSM10008 | B9: C0328 | C9: Client 0328 | D9: 2026-12-06 | E9: content marketing | F9: Content Marketing | G9: Healthcare | H9: Pune | I9: New | J9: Completed | K9: 10 | L9: 39.0 | M9: 40300.0 | N9: 4000.0 | O9: 36300.0 | P9: 23300.0 | Q9: 13000.0 | R9: 35.81 | S9: Google | T9: 4500.0 | U9: 4.9 | V9: Social
A10: JSM10009 | B10: C0138 | C10: Client 0138 | D10: 2025-03-09 | E10: online reputation management | F10: Online Reputation Management | G10: Finance | H10: Pune | I10: Returning | J10: Delayed | K10: 5 | L10: 19.0 | M10: 18600.0 | N10: 2800.0 | O10: 15800.0 | P10: 9800.0 | Q10: 6000.0 | R10: 37.97 | S10: Partner | T10: 1900.0 | U10: 4.2 | V10: Referral
A11: JSM10010 | B11: C0330 | C11: Client 0330 | D11: 2026-04-15 | E11: ORM | F11: Online Reputation Management | G11: Hospitality | H11: Ahmedabad | I11: New | J11: Completed | K11: 4 | L11: 45.0 | M11: 26300.0 | N11: 0.0 | O11: 26300.0 | P11: 12800.0 | Q11: 13500.0 | R11: 51.33 | S11: Email Campaign | T11: 4700.0 | U11: 3.4 | V11: Referral
A12: JSM10011 | B12: C0113 | C12: Client 0113 | D12: 2025-05-22 | E12: PPC | F12: PPC | G12: Education | H12: Bengaluru | I12: Returning | J12: Completed | K12: 10 | L12: 25.0 | M12: 62100.0 | N12: 3100.0 | O12: 59000.0 | P12: 26200.0 | Q12: 32800.0 | R12: 55.59 | S12: Partner | T12: 4000.0 | V12: Paid Search
A13: JSM10012 | B13: C0306 | C13: Client 0306 | D13: 2025-03-07 | E13: Online Reputation Management | F13: Online Reputation Management | G13: Hospitality | H13: Mumbai | I13: New | J13: Completed | K13: 8 | L13: 50.0 | M13: 65100.0 | N13: 6500.0 | O13: 58600.0 | P13: 44300.0 | Q13: 14300.0 | R13: 24.4 | S13: Partner | T13: 9400.0 | U13: 4.2 | V13: Organic Search
A14: JSM10013 | B14: C0394 | C14: Client 0394 | D14: 2026-10-19 | E14: content marketing | F14: Content Marketing | G14: E-commerce | H14: Kolkata | I14: New | J14: Completed | K14: 7 | L14: 10.0 | M14: 81200.0 | N14: 16200.0 | O14: 65000.0 | P14: 36200.0 | Q14: 28800.0 | R14: 44.31 | S14: Google | T14: 5600.0 | V14: Social
A15: JSM10014 | B15: C0260 | C15: Client 0260 | D15: 2025-04-19 | E15: Web Designing | F15: Web Design | G15: E-commerce | H15: Chennai | I15: New | J15: Delayed | K15: 6 | L15: 62.0 | M15: 42600.0 | N15: 8500.0 | O15: 34100.0 | P15: 19900.0 | Q15: 14200.0 | R15: 41.64 | S15: Referral | T15: 5400.0 | U15: 4.8 | V15: Direct
A16: JSM10015 | B16: C0307 | C16: Client 0307 | D16: 2025-11-28 | E16: seo | F16: SEO | G16: Hospitality | H16: Pune | I16: New | J16: Completed | K16: 9 | L16: 21.0 | M16: 68300.0 | N16: 3400.0 | O16: 64900.0 | P16: 35700.0 | Q16: 29200.0 | R16: 44.99 | S16: Google | T16: 7300.0 | U16: 3.8 | V16: Paid Search
A17: JSM10016 | B17: C0044 | C17: Client 0044 | D17: 2026-05-13 | E17: SMM | F17: Social Media Marketing | G17: E-commerce | H17: Kolkata | I17: Returning | J17: Cancelled | K17: 3 | L17: 36.0 | M17: 20300.0 | N17: 4100.0 | O17: 16200.0 | P17: 12700.0 | Q17: 3500.0 | R17: 21.6 | S17: Email Campaign | T17: 1000.0 | U17: 4.8 | V17: Paid Search
A18: JSM10017 | B18: C0271 | C18: Client 0271 | D18: 2026-09-14 | E18: Content Marketing | F18: Content Marketing | G18: Real Estate | H18: Hyderabad | I18: New | J18: Cancelled | K18: 8 | L18: 53.0 | M18: 156100.0 | N18: 23400.0 | O18: 132700.0 | P18: 78200.0 | Q18: 54500.0 | R18: 41.07 | S18: Direct | T18: 6700.0 | U18: 3.6 | V18: Social
A19: JSM10018 | B19: C0265 | C19: Client 0265 | D19: 2026-04-08 | E19: Mobile App Development | F19: Mobile App Development | G19: Finance | H19: Mumbai | I19: New | J19: Completed | K19: 3 | L19: 28.0 | M19: 73400.0 | N19: 7300.0 | O19: 66100.0 | P19: 54400.0 | Q19: 11700.0 | R19: 17.7 | S19: Email Campaign | T19: 6500.0 | U19: 4.3 | V19: Direct
A20: JSM10019 | B20: C0302 | C20: Client 0302 | D20: 2025-08-14 | E20: Web Development | F20: Web Development | G20: Real Estate | H20: Delhi NCR | I20: New | J20: Completed | K20: 2 | L20: 31.0 | M20: 67000.0 | N20: 0.0 | O20: 67000.0 | P20: 31400.0 | Q20: 35600.0 | R20: 53.13 | S20: Google | T20: 5700.0 | U20: 3.9 | V20: Social
A21: JSM10020 | B21: C0264 | C21: Client 0264 | D21: 2025-09-01 | E21: SMM | F21: Social Media Marketing | G21: E-commerce | H21: Kolkata | I21: New | J21: Ongoing | K21: 6 | L21: 31.0 | M21: 89400.0 | N21: 17900.0 | O21: 71500.0 | P21: 68300.0 | Q21: 3200.0 | R21: 4.48 | S21: Referral | T21: 8000.0 | U21: 3.9 | V21: Referral
A22: JSM10021 | B22: C0098 | C22: Client 0098 | D22: 2025-04-07 | E22: Online Reputation Management | F22: Online Reputation Management | G22: Manufacturing | H22: Ahmedabad | I22: Returning | J22: Ongoing | K22: 3 | L22: 12.0 | M22: 35200.0 | N22: 3500.0 | O22: 31700.0 | P22: 16500.0 | Q22: 15200.0 | R22: 47.95 | S22: Direct | T22: 2400.0 | U22: 3.8 | V22: Organic Search
A23: JSM10022 | B23: C0032 | C23: Client 0032 | D23: 2026-02-17 | E23: Social Media Marketing | F23: Social Media Marketing | G23: Real Estate | H23: Pune | I23: Returning | J23: Ongoing | K23: 7 | L23: 27.0 | M23: 15000.0 | N23: 0.0 | O23: 15000.0 | P23: 6700.0 | Q23: 8300.0 | R23: 55.33 | S23: Referral | T23: 2600.0 | U23: 4.9 | V23: Direct
A24: JSM10023 | B24: C0072 | C24: Client 0072 | D24: 2026-03-09 | E24: Mobile App Development | F24: Mobile App Development | G24: Education | H24: Kolkata | I24: Returning | J24: Completed | K24: 4 | L24: 37.0 | M24: 17700.0 | N24: 0.0 | O24: 17700.0 | P24: 9600.0 | Q24: 8100.0 | R24: 45.76 | S24: Email Campaign | T24: 3200.0 | U24: 3.8 | V24: Organic Search
A25: JSM10024 | B25: C0334 | C25: Client 0334 | D25: 2026-07-08 | E25: Search Engine Optimization | F25: SEO | G25: E-commerce | H25: Ahmedabad | I25: New | J25: Cancelled | K25: 2 | L25: 36.0 | M25: 87600.0 | N25: 13100.0 | O25: 74500.0 | P25: 60600.0 | Q25: 13900.0 | R25: 18.66 | S25: Direct | T25: 8100.0 | U25: 3.2 | V25: Referral
A26: JSM10025 | B26: C0206 | C26: Client 0206 | D26: 2025-03-02 | E26: Web Development | F26: Web Development | G26: Hospitality | H26: Kolkata | I26: New | J26: Completed | K26: 4 | L26: 58.0 | M26: 67100.0 | N26: 13400.0 | O26: 53700.0 | P26: 34600.0 | Q26: 19100.0 | R26: 35.57 | S26: Social Media | T26: 4900.0 | U26: 5.0 | V26: Referral
... A57: JSM10056 | B57: C0386 | C57: Client 0386 | D57: 2026-02-04 | E57: Content Marketing | F57: Content Marketing | G57: Real Estate | H57: Kolkata | I57: New | J57: Completed | K57: 8 | L57: 70.0 | M57: 50300.0 | N57: 5000.0 | O57: 45300.0 | P57: 37600.0 | Q57: 7700.0 | R57: 17.0 | S57: Referral | T57: 4300.0 | U57: 3.9 | V57: Social
A58: JSM10057 | B58: C0249 | C58: Client 0249 | D58: 2025-01-30 | E58: online reputation management | F58: Online Reputation Management | G58: Manufacturing | H58: Bengaluru | I58: New | J58: Completed | K58: 8 | L58: 43.0 | M58: 31500.0 | O58: 26800.0 | P58: 14100.0 | Q58: 12700.0 | R58: 47.39 | S58: Direct | T58: 4200.0 | U58: 3.7 | V58: Paid Search
A59: JSM10058 | B59: C0202 | C59: Client 0202 | D59: 2026-08-30 | E59: SEO | F59: SEO | G59: E-commerce | H59: Kolkata | I59: New | J59: Completed | K59: 2 | L59: 31.0 | M59: 74900.0 | N59: 7500.0 | O59: 67400.0 | P59: 57700.0 | Q59: 9700.0 | R59: 14.39 | S59: Referral | T59: 6600.0 | U59: 5.0 | V59: Organic Search
A60: JSM10059 | B60: C0195 | C60: Client 0195 | D60: 2025-12-02 | E60: content marketing | F60: Content Marketing | G60: Manufacturing | H60: Hyderabad | I60: New | J60: Completed | K60: 5 | L60: 38.0 | M60: 58200.0 | N60: 2900.0 | O60: 55300.0 | P60: 34300.0 | Q60: 21000.0 | R60: 37.97 | S60: Direct | T60: 9900.0 | U60: 2.9 | V60: Social
A61: JSM10060 | B61: C0241 | C61: Client 0241 | D61: 2025-01-20 | E61: social media marketing | F61: Social Media Marketing | G61: Real Estate | H61: Delhi NCR | I61: New | J61: Completed | K61: 10 | L61: 16.0 | M61: 30700.0 | N61: 4600.0 | O61: 26100.0 | P61: 24300.0 | Q61: 1800.0 | R61: 6.9 | S61: Partner | T61: 1900.0 | U61: 4.9 | V61: Organic Search
A62: JSM10061 | B62: C0127 | C62: Client 0127 | D62: 2025-07-24 | E62: Search Engine Optimization | F62: SEO | G62: E-commerce | H62: Kolkata | I62: Returning | J62: Ongoing | K62: 2 | L62: 58.0 | M62: 71100.0 | N62: 14200.0 | O62: 56900.0 | P62: 36600.0 | Q62: 20300.0 | R62: 35.68 | S62: Partner | T62: 9500.0 | U62: 4.9 | V62: Organic Search
A63: JSM10062 | B63: C0239 | C63: Client 0239 | D63: 2026-12-18 | E63: Web Dev | F63: Web Development | G63: Education | H63: Bengaluru | I63: New | J63: Ongoing | K63: 6 | L63: 38.0 | M63: 64500.0 | N63: 6400.0 | O63: 58100.0 | P63: 37100.0 | Q63: 21000.0 | R63: 36.14 | S63: Social Media | T63: 10100.0 | U63: 3.9 | V63: Organic Search
A64: JSM10063 | B64: C0160 | C64: Client 0160 | D64: 2026-08-13 | E64: Search Engine Optimization | F64: SEO | G64: Education | H64: Pune | I64: Returning | J64: Completed | K64: 8 | L64: 30.0 | M64: 76200.0 | N64: 7600.0 | O64: 68600.0 | P64: 61200.0 | Q64: 7400.0 | R64: 10.79 | S64: Google | T64: 8300.0 | U64: 3.6 | V64: Social
A65: JSM10064 | B65: C0408 | C65: Client 0408 | D65: 2026-08-03 | E65: SMM | F65: Social Media Marketing | G65: Finance | H65: Delhi NCR | I65: New | J65: Completed | K65: 2 | L65: 75.0 | M65: 25500.0 | N65: 2600.0 | O65: 22900.0 | P65: 17600.0 | Q65: 5300.0 | R65: 23.14 | S65: Email Campaign | T65: 3900.0 | U65: 3.3 | V65: Social
A66: JSM10065 | B66: C0216 | C66: Client 0216 | D66: 2026-05-17 | E66: seo | F66: SEO | G66: B2B Services | H66: Bengaluru | I66: New | J66: Completed | K66: 3 | L66: 31.0 | M66: 50900.0 | N66: 0.0 | O66: 50900.0 | P66: 40300.0 | Q66: 10600.0 | R66: 20.83 | S66: Direct | T66: 2400.0 | U66: 2.7 | V66: Paid Search
A67: JSM10066 | B67: C0316 | C67: Client 0316 | D67: 2026-07-06 | E67: Content Marketing | F67: Content Marketing | G67: Hospitality | H67: Chennai | I67: New | J67: Completed | K67: 9 | L67: 69.0 | M67: 37400.0 | N67: 3700.0 | O67: 33700.0 | P67: 17500.0 | Q67: 16200.0 | R67: 48.07 | S67: Referral | T67: 4600.0 | U67: 4.6 | V67: Organic Search
A68: JSM10067 | B68: C0231 | C68: Client 0231 | D68: 2025-09-07 | E68: Content Marketing | F68: Content Marketing | G68: Manufacturing | H68: Chennai | I68: New | J68: Completed | K68: 9 | L68: 39.0 | M68: 46400.0 | N68: 9300.0 | O68: 37100.0 | P68: 35100.0 | Q68: 2000.0 | R68: 5.39 | S68: Google | T68: 5100.0 | U68: 3.8 | V68: Referral
A69: JSM10068 | B69: C0094 | C69: Client 0094 | D69: 2026-05-15 | E69: ppc | F69: PPC | G69: Finance | H69: Hyderabad | I69: Returning | J69: Completed | K69: 5 | L69: 42.0 | M69: 20000.0 | N69: 0.0 | O69: 20000.0 | P69: 14900.0 | Q69: 5100.0 | R69: 25.5 | S69: Email Campaign | T69: 2500.0 | U69: 3.2 | V69: Social
A70: JSM10069 | B70: C0265 | C70: Client 0265 | D70: 2025-07-15 | E70: SEO | F70: SEO | G70: B2B Services | H70: Pune | I70: New | J70: Completed | K70: 3 | L70: 61.0 | M70: 26200.0 | N70: 2600.0 | O70: 23600.0 | P70: 16100.0 | Q70: 7500.0 | R70: 31.78 | S70: Partner | T70: 2800.0 | U70: 4.7 | V70: Referral
...

Sheet Cleaned_Data
A1: Project_ID | B1: Client_ID | C1: Client_Name | D1: Project_Date | E1: Service | F1: Service_Category | G1: Industry | H1: Region | I1: Client_Type | J1: Project_Status | K1: Team_Size | L1: Project_Duration_Days | M1: Quoted_Value | N1: Discount | O1: Revenue | P1: Project_Cost | Q1: Profit | R1: Profit_Margin_Pct | S1: Lead_Source | T1: Marketing_Spend | U1: Customer_Rating | V1: Acquisition_Channel
A2: JSM10088 | B2: C0264 | C2: Client 0264 | D2: 45659 | E2: Online Reputation Management | F2: Online Reputation Management | G2: Real Estate | H2: Chennai | I2: New | J2: Completed | K2: 10 | L2: 68 | M2: 71400 | N2: 0 | O2: 71400 | P2: 38500 | Q2: 32900 | R2: 46.08 | S2: Email Campaign | T2: 11500 | U2: 4 | V2: Referral
A3: JSM10700 | B3: C0014 | C3: Client 0014 | D3: 45660 | E3: Web Development | F3: Web Development | G3: Education | H3: Hyderabad | I3: Returning | J3: Completed | K3: 4 | L3: 41 | M3: 88400 | N3: 17700 | O3: 70700 | P3: 52300 | Q3: 18400 | R3: 26.03 | S3: Direct | T3: 11900 | U3: 4.4 | V3: Paid Search
A4: JSM10034 | B4: C0023 | C4: Client 0023 | D4: 45661 | E4: Content Marketing | F4: Content Marketing | G4: Hospitality | H4: Bengaluru | I4: Returning | J4: Ongoing | K4: 7 | L4: 52 | M4: 83900 | N4: 4200 | O4: 79700 | P4: 57000 | Q4: 22700 | R4: 28.48 | S4: Partner | T4: 10500 | U4: 3.6 | V4: Referral
A5: JSM10392 | B5: C0347 | C5: Client 0347 | D5: 45662 | E5: SEO | F5: SEO | G5: Hospitality | H5: Bengaluru | I5: New | J5: Completed | K5: 5 | M5: 141500 | N5: 0 | O5: 141500 | P5: 92100 | Q5: 49400 | R5: 34.91 | S5: Google | T5: 5800 | U5: 4.6 | V5: Referral
A6: JSM10418 | B6: C0256 | C6: Client 0256 | D6: 45662 | E6: Web Design | F6: Web Design | G6: B2B Services | H6: Bengaluru | I6: New | J6: Ongoing | K6: 10 | L6: 71 | M6: 61400 | N6: 3100 | O6: 58300 | P6: 47400 | Q6: 10900 | R6: 18.7 | S6: Partner | T6: 2500 | U6: 5 | V6: Direct
A7: JSM11149 | B7: C0344 | C7: Client 0344 | D7: 45664 | E7: Online Reputation Management | F7: Online Reputation Management | G7: B2B Services | H7: Mumbai | I7: New | J7: Ongoing | K7: 9 | L7: 15 | M7: 75200 | N7: 11300 | O7: 63900 | P7: 45400 | Q7: 18500 | R7: 28.95 | S7: Google | T7: 6400 | U7: 4.3 | V7: Organic Search
A8: JSM10539 | B8: C0155 | C8: Client 0155 | D8: 45664 | E8: Web Design | F8: Web Design | G8: Finance | H8: Mumbai | I8: Returning | J8: Cancelled | K8: 6 | L8: 36 | M8: 34600 | N8: 3500 | O8: 31100 | P8: 15700 | Q8: 15400 | R8: 49.52 | S8: Partner | T8: 5100 | U8: 4.3 | V8: Social
A9: JSM10811 | B9: C0394 | C9: Client 0394 | D9: 45664 | E9: Online Reputation Management | F9: Online Reputation Management | G9: Finance | H9: Hyderabad | I9: New | J9: Ongoing | K9: 5 | L9: 5 | M9: 33400 | N9: 6700 | O9: 26700 | P9: 26900 | Q9: -200 | R9: -0.75 | S9: Email Campaign | T9: 3600 | U9: 3.5 | V9: Paid Search
A10: JSM10440 | B10: C0274 | C10: Client 0274 | D10: 45664 | E10: Social Media Marketing | F10: Social Media Marketing | G10: Education | H10: Chennai | I10: New | J10: Ongoing | K10: 3 | L10: 73 | M10: 60000 | N10: 3000 | O10: 57000 | P10: 43400 | Q10: 13600 | R10: 23.86 | S10: Email Campaign | T10: 3400 | U10: 5 | V10: Organic Search
A11: JSM10003 | B11: C0415 | C11: Client 0415 | D11: 45664 | E11: Content Marketing | F11: Content Marketing | G11: Hospitality | H11: Bengaluru | I11: New | J11: Ongoing | K11: 4 | L11: 27 | M11: 33200 | N11: 3300 | O11: 29900 | P11: 16400 | Q11: 13500 | R11: 45.15 | S11: Referral | T11: 3800 | U11: 2.5 | V11: Social
A12: JSM10902 | B12: C0104 | C12: Client 0104 | D12: 45665 | E12: Content Marketing | F12: Content Marketing | G12: Real Estate | H12: Chennai | I12: Returning | J12: Completed | K12: 4 | L12: 32 | M12: 83300 | N12: 8300 | O12: 75000 | P12: 35200 | Q12: 39800 | R12: 53.07 | S12: Email Campaign | T12: 10500 | U12: 2.3 | V12: Referral
A13: JSM10137 | B13: C0062 | C13: Client 0062 | D13: 45665 | E13: PPC | F13: PPC | G13: E-commerce | H13: Ahmedabad | I13: Returning | J13: Ongoing | K13: 9 | L13: 43 | M13: 38600 | N13: 0 | O13: 38600 | P13: 30800 | Q13: 7800 | R13: 20.21 | S13: Email Campaign | T13: 3000 | U13: 3.4 | V13: Paid Search
A14: JSM11301 | B14: C0077 | C14: Client 0077 | D14: 45665 | E14: Social Media Marketing | F14: Social Media Marketing | G14: Real Estate | H14: Kolkata | I14: Returning | J14: Delayed | K14: 7 | L14: 40 | M14: 65400 | N14: 9800 | O14: 55600 | P14: 41600 | Q14: 14000 | R14: 25.18 | S14: Direct | T14: 3900 | U14: 2.6 | V14: Organic Search
A15: JSM11252 | B15: C0205 | C15: Client 0205 | D15: 45667 | E15: Online Reputation Management | F15: Online Reputation Management | G15: Hospitality | H15: Chennai | I15: New | J15: Completed | K15: 6 | L15: 13 | M15: 45100 | N15: 4500 | O15: 40600 | P15: 35300 | Q15: 5300 | R15: 13.05 | S15: Email Campaign | T15: 4000 | U15: 4.4 | V15: Social
A16: JSM10035 | B16: C0288 | C16: Client 0288 | D16: 45667 | E16: Online Reputation Management | F16: Online Reputation Management | G16: E-commerce | H16: Mumbai | I16: New | J16: Completed | K16: 3 | L16: 22 | M16: 48100 | N16: 9600 | O16: 38500 | P16: 27300 | Q16: 11200 | R16: 29.09 | S16: Social Media | T16: 2900 | U16: 4 | V16: Direct
A17: JSM10216 | B17: C0020 | C17: Client 0020 | D17: 45667 | E17: Content Marketing | F17: Content Marketing | G17: Finance | H17: Hyderabad | I17: Returning | J17: Completed | K17: 6 | L17: 33 | M17: 15000 | N17: 0 | O17: 15000 | P17: 11300 | Q17: 3700 | R17: 24.67 | S17: Direct | T17: 1500 | U17: 4.3 | V17: Direct
... A26: JSM11117 | B26: C0109 | C26: Client 0109 | D26: 45671 | E26: SEO | F26: SEO | G26: Real Estate | H26: Kolkata | I26: Returning | J26: Completed | K26: 5 | L26: 38 | M26: 38300 | N26: 5700 | O26: 32600 | P26: 31000 | Q26: 1600 | R26: 4.91 | S26: Google | T26: 1900 | U26: 4.5 | V26: Social
A27: JSM11462 | B27: C0292 | C27: Client 0292 | D27: 45672 | E27: SEO | F27: SEO | G27: E-commerce | H27: Chennai | I27: New | J27: Completed | K27: 4 | L27: 33 | M27: 15000 | N27: 3000 | O27: 12000 | P27: 10600 | Q27: 1400 | R27: 11.67 | S27: Direct | T27: 1300 | V27: Paid Search
A28: JSM10074 | B28: C0155 | C28: Client 0155 | D28: 45672 | E28: Web Design | F28: Web Design | G28: Healthcare | H28: Hyderabad | I28: Returning | J28: Completed | K28: 10 | L28: 20 | M28: 97800 | N28: 0 | O28: 97800 | P28: 76900 | Q28: 20900 | R28: 21.37 | S28: Partner | T28: 16900 | U28: 3.6 | V28: Paid Search
A29: JSM10991 | B29: C0208 | C29: Client 0208 | D29: 45672 | E29: Social Media Marketing | F29: Social Media Marketing | G29: Manufacturing | H29: Chennai | I29: New | J29: Delayed | K29: 5 | L29: 52 | M29: 63500 | N29: 6400 | O29: 57100 | P29: 33500 | Q29: 23600 | R29: 41.33 | S29: Referral | T29: 6000 | U29: 3.3 | V29: Direct
A30: JSM11181 | B30: C0411 | C30: Client 0411 | D30: 45673 | E30: SEO | F30: SEO | G30: Healthcare | H30: Bengaluru | I30: New | J30: Ongoing | K30: 5 | L30: 19 | M30: 100000 | N30: 0 | O30: 100000 | P30: 47800 | Q30: 52200 | R30: 52.2 | S30: Direct | T30: 16600 | U30: 4.1 | V30: Paid Search
A31: JSM11241 | B31: C0011 | C31: Client 0011 | D31: 45673 | E31: Online Reputation Management | F31: Online Reputation Management | G31: Education | H31: Ahmedabad | I31: Returning | J31: Completed | K31: 10 | L31: 55 | M31: 17000 | N31: 800 | O31: 16200 | P31: 10200 | Q31: 6000 | R31: 37.04 | S31: Referral | T31: 1600 | U31: 3.8 | V31: Direct
A32: JSM10465 | B32: C0056 | C32: Client 0056 | D32: 45674 | E32: Web Design | F32: Web Design | G32: E-commerce | H32: Delhi Ncr | I32: Returning | J32: Completed | K32: 5 | L32: 30 | M32: 40500 | N32: 4000 | O32: 36500 | P32: 23100 | Q32: 13400 | R32: 36.71 | S32: Referral | T32: 6500 | U32: 4.6 | V32: Referral
A33: JSM10795 | B33: C0418 | C33: Client 0418 | D33: 45674 | E33: Social Media Marketing | F33: Social Media Marketing | G33: B2B Services | H33: Bengaluru | I33: New | J33: Delayed | K33: 5 | L33: 46 | M33: 49400 | N33: 9900 | O33: 39500 | P33: 32100 | Q33: 7400 | R33: 18.73 | S33: Partner | T33: 5800 | U33: 4.7 | V33: Paid Search
A34: JSM10914 | B34: C0047 | C34: Client 0047 | D34: 45674 | E34: Web Development | F34: Web Development | G34: Finance | H34: Pune | I34: Returning | J34: Completed | K34: 8 | L34: 56 | M34: 39700 | N34: 2000 | O34: 37700 | P34: 18300 | Q34: 19400 | R34: 51.46 | S34: Partner | T34: 3300 | U34: 4.5 | V34: Organic Search
A35: JSM11121 | B35: C0124 | C35: Client 0124 | D35: 45674 | E35: Social Media Marketing | F35: Social Media Marketing | G35: B2B Services | H35: Kolkata | I35: Returning | J35: Completed | K35: 9 | L35: 87 | M35: 18900 | N35: 1900 | O35: 17000 | P35: 9200 | Q35: 7800 | R35: 45.88 | S35: Social Media | T35: 2700 | U35: 4 | V35: Social
A36: JSM10070 | B36: C0230 | C36: Client 0230 | D36: 45675 | E36: Mobile App Development | F36: Mobile App Development | G36: Real Estate | H36: Hyderabad | I36: New | J36: Completed | K36: 3 | L36: 35 | M36: 43900 | N36: 4400 | O36: 39500 | P36: 18600 | Q36: 20900 | R36: 52.91 | S36: Partner | T36: 4700 | U36: 3.4 | V36: Direct
A37: JSM10060 | B37: C0241 | C37: Client 0241 | D37: 45677 | E37: Social Media Marketing | F37: Social Media Marketing | G37: Real Estate | H37: Delhi Ncr | I37: New | J37: Completed | K37: 10 | L37: 16 | M37: 30700 | N37: 4600 | O37: 26100 | P37: 24300 | Q37: 1800 | R37: 6.9 | S37: Partner | T37: 1900 | U37: 4.9 | V37: Organic Search
A38: JSM10650 | B38: C0335 | C38: Client 0335 | D38: 45677 | E38: Mobile App Development | F38: Mobile App Development | G38: Healthcare | H38: Pune | I38: New | J38: Delayed | K38: 9 | L38: 44 | M38: 37700 | N38: 1900 | O38: 35800 | P38: 30400 | Q38: 5400 | R38: 15.08 | S38: Partner | T38: 3800 | U38: 3.9 | V38: Paid Search
A39: JSM10205 | B39: C0098 | C39: Client 0098 | D39: 45677 | E39: Social Media Marketing | F39: Social Media Marketing | G39: Manufacturing | H39: Pune | I39: Returning | J39: Completed | K39: 9 | L39: 49 | M39: 105000 | N39: 0 | O39: 105000 | P39: 71400 | Q39: 33600 | R39: 32 | S39: Direct | T39: 17000 | U39: 3.4 | V39: Direct
... A126: JSM10860 | B126: C0160 | C126: Client 0160 | D126: 45722 | E126: PPC | F126: PPC | G126: Healthcare | H126: Chennai | I126: Returning | J126: Completed | K126: 3 | L126: 12 | M126: 51500 | N126: 2600 | O126: 48900 | P126: 39700 | Q126: 9200 | R126: 18.81 | S126: Social Media | T126: 5600 | U126: 3.7 | V126: Paid Search
A127: JSM10265 | B127: C0075 | C127: Client 0075 | D127: 45722 | E127: Mobile App Development | F127: Mobile App Development | G127: Hospitality | H127: Kolkata | I127: Returning | J127: Completed | K127: 4 | M127: 59400 | N127: 5900 | O127: 53500 | P127: 47900 | Q127: 5600 | R127: 10.47 | S127: Google | T127: 4500 | U127: 2.2 | V127: Social
A128: JSM10121 | B128: C0382 | C128: Client 0382 | D128: 45723 | E128: Social Media Marketing | F128: Social Media Marketing | G128: Education | H128: Kolkata | I128: New | J128: Completed | K128: 9 | L128: 39 | M128: 26300 | N128: 0 | O128: 26300 | P128: 15000 | Q128: 11300 | R128: 42.97 | S128: Email Campaign | T128: 1300 | U128: 4.9 | V128: Paid Search
A129: JSM11434 | B129: C0315 | C129: Client 0315 | D129: 45723 | E129: Social Media Marketing | F129: Social Media Marketing | G129: Real Estate | H129: Pune | I129: New | J129: Completed | K129: 10 | L129: 18 | M129: 131700 | N129: 0 | O129: 131700 | P129: 88700 | Q129: 43000 | R129: 32.65 | S129: Email Campaign | T129: 6100 | U129: 4.1 | V129: Paid Search
A130: JSM10012 | B130: C0306 | C130: Client 0306 | D130: 45723 | E130: Online Reputation Management | F130: Online Reputation Management | G130: Hospitality | H130: Mumbai | I130: New | J130: Completed | K130: 8 | L130: 50 | M130: 65100 | N130: 6500 | O130: 58600 | P130: 44300 | Q130: 14300 | R130: 24.4 | S130: Partner | T130: 9400 | U130: 4.2 | V130: Organic Search
A131: JSM10182 | B131: C0364 | C131: Client 0364 | D131: 45724 | E131: PPC | F131: PPC | G131: E-commerce | H131: Bengaluru | I131: New | J131: Completed | K131: 10 | L131: 53 | M131: 63500 | N131: 0 | O131: 63500 | P131: 29600 | Q131: 33900 | R131: 53.39 | S131: Social Media | T131: 8200 | U131: 2.9 | V131: Direct
A132: JSM10076 | B132: C0059 | C132: Client 0059 | D132: 45724 | E132: Mobile App Development | F132: Mobile App Development | G132: Healthcare | H132: Bengaluru | I132: Returning | J132: Completed | K132: 8 | L132: 28 | M132: 29200 | N132: 1500 | O132: 27700 | P132: 23600 | Q132: 4100 | R132: 14.8 | S132: Referral | T132: 3800 | U132: 4.2 | V132: Direct
A133: JSM10393 | B133: C0086 | C133: Client 0086 | D133: 45724 | E133: Content Marketing | F133: Content Marketing | G133: B2B Services | H133: Chennai | I133: Returning | J133: Completed | K133: 2 | L133: 25 | M133: 53400 | N133: 5300 | O133: 48100 | P133: 40400 | Q133: 7700 | R133: 16.01 | S133: Direct | T133: 6700 | U133: 3.1 | V133: Paid Search
A134: JSM10734 | B134: C0353 | C134: Client 0353 | D134: 45725 | E134: Social Media Marketing | F134: Social Media Marketing | G134: Healthcare | H134: Chennai | I134: New | J134: Completed | K134: 6 | L134: 23 | M134: 47600 | N134: 0 | O134: 47600 | P134: 33500 | Q134: 14100 | R134: 29.62 | S134: Google | T134: 2600 | U134: 4 | V134: Referral
...

Sheet Cleaning_Log
A1: Column / Area | B1: Issue / Check | C1: Records affected | D1: Action taken
A2: All columns | B2: Exact duplicate records | C2: 11 | D2: Removed exact duplicate rows; first occurrence retained.
A3: Region | B3: Missing values | C3: 18 | D3: Replaced missing values with 'Unknown'.
A4: Industry | B4: Missing values | C4: 8 | D4: Replaced missing values with 'Unknown'.
A5: Lead_Source | B5: Missing values | C5: 12 | D5: Replaced missing values with 'Unknown'.
A6: Customer_Rating | B6: Missing values | C6: 15 | D6: Kept blank because the true value cannot safely be inferred.
A7: Project_Duration_Days | B7: Missing values | C7: 10 | D7: Kept blank because the true value cannot safely be inferred.
A8: Discount | B8: Missing values | C8: 10 | D8: Replaced missing values with 0 (treated as no discount).
A9: Service | B9: Inconsistent text/capitalization/spacing | C9: 1091 | D9: Standardized to one canonical format.
A10: Region | B10: Inconsistent text/capitalization/spacing | C10: 208 | D10: Standardized to one canonical format.
A11: Client_Type | B11: Inconsistent text/capitalization/spacing | C11: 15 | D11: Standardized to one canonical format.
A12: Project_Status | B12: Inconsistent text/capitalization/spacing | C12: 12 | D12: Standardized to one canonical format.
A13: Project_Date | B13: Date conversion | C13: 1501 | D13: Converted ISO and DD/MM/YYYY values to proper dates.
... A29: Profit_Margin_Pct | B29: Logical consistency | C29: 11 | D29: Recalculated as Profit / Revenue × 100.

Sheet Data_Dictionary
A1: Column | B1: Meaning
A2: Project_ID | B2: Unique project identifier
A3: Client_ID | B3: Unique client identifier
A4: Client_Name | B4: Client display name
A5: Project_Date | B5: Project start/date
A6: Service | B6: Service delivered
A7: Service_Category | B7: Service grouping
A8: Industry | B8: Client industry
A9: Region | B9: Client region
A10: Client_Type | B10: New or returning client
A11: Project_Status | B11: Project status
A12: Team_Size | B12: Number of team members
... A30: Marketing_ROI | B30: Marketing ROI

Sheet Beginner_Analysis
A1: BEGINNER BUSINESS ANALYSIS
A3: KPI | B3: Value
A4: Total Revenue | B4: =SUM(SalesData[Revenue]) -> 69877300
A5: Total Profit | B5: =SUM(SalesData[Profit]) -> 22734300
A6: Total Projects | B6: =COUNTA(SalesData[Project_ID]) -> 1501
A7: Total Clients | B7: =SUMPRODUCT(1/COUNTIF(SalesData[Client_ID],SalesData[Client_ID])) -> 405
A8: Average Project Value | B8: =AVERAGE(SalesData[Quoted_Value]) -> 50758.095
A9: Average Profit Margin | B9: =AVERAGE(SalesData[Profit_Margin_Pct]) -> 31.842978
A10: Average Customer Rating | B10: =AVERAGE(SalesData[Customer_Rating]) -> 4.0634459
A13: MONTHLY REVENUE ANALYSIS
A14: Month | B14: Revenue | C14: Profit | D14: Projects | E14: Avg Profit Margin
A15: 45658 | B15: =SUMIFS(SalesData[Revenue],SalesData[Project_Date],">="&A15,SalesData[Project_Date],"<"&EDATE(A15,1)) -> 2823200 | C15: =SUMIFS(SalesData[Profit],SalesData[Project_Date],">="&A15,SalesData[Project_Date],"<"&EDATE(A15,1)) -> 901400 | D15: =COUNTIFS(SalesData[Project_Date],">="&A15,SalesData[Project_Date],"<"&EDATE(A15,1)) -> 59 | E15: =IFERROR(AVERAGEIFS(SalesData[Profit_Margin_Pct],SalesData[Project_Date],">="&A15,SalesData[Project_Date],"<"&EDATE(A15,1)),0) -> 30.623898
A16: 45689 | B16: =SUMIFS(SalesData[Revenue],SalesData[Project_Date],">="&A16,SalesData[Project_Date],"<"&EDATE(A16,1)) -> 2622300 | C16: =SUMIFS(SalesData[Profit],SalesData[Project_Date],">="&A16,SalesData[Project_Date],"<"&EDATE(A16,1)) -> 847800 | D16: =COUNTIFS(SalesData[Project_Date],">="&A16,SalesData[Project_Date],"<"&EDATE(A16,1)) -> 56 | E16: =IFERROR(AVERAGEIFS(SalesData[Profit_Margin_Pct],SalesData[Project_Date],">="&A16,SalesData[Project_Date],"<"&EDATE(A16,1)),0) -> 31.15125
A17: 45717 | B17: =SUMIFS(SalesData[Revenue],SalesData[Project_Date],">="&A17,SalesData[Project_Date],"<"&EDATE(A17,1)) -> 2921200 | C17: =SUMIFS(SalesData[Profit],SalesData[Project_Date],">="&A17,SalesData[Project_Date],"<"&EDATE(A17,1)) -> 957800 | D17: =COUNTIFS(SalesData[Project_Date],">="&A17,SalesData[Project_Date],"<"&EDATE(A17,1)) -> 60 | E17: =IFERROR(AVERAGEIFS(SalesData[Profit_Margin_Pct],SalesData[Project_Date],">="&A17,SalesData[Project_Date],"<"&EDATE(A17,1)),0) -> 32.729667
A18: 45748 | B18: =SUMIFS(SalesData[Revenue],SalesData[Project_Date],">="&A18,SalesData[Project_Date],"<"&EDATE(A18,1)) -> 3502500 | C18: =SUMIFS(SalesData[Profit],SalesData[Project_Date],">="&A18,SalesData[Project_Date],"<"&EDATE(A18,1)) -> 1139800 | D18: =COUNTIFS(SalesData[Project_Date],">="&A18,SalesData[Project_Date],"<"&EDATE(A18,1)) -> 67 | E18: =IFERROR(AVERAGEIFS(SalesData[Profit_Margin_Pct],SalesData[Project_Date],">="&A18,SalesData[Project_Date],"<"&EDATE(A18,1)),0) -> 32.155224
A19: 45778 | B19: =SUMIFS(SalesData[Revenue],SalesData[Project_Date],">="&A19,SalesData[Project_Date],"<"&EDATE(A19,1)) -> 3582200 | C19: =SUMIFS(SalesData[Profit],SalesData[Project_Date],">="&A19,SalesData[Project_Date],"<"&EDATE(A19,1)) -> 1056200 | D19: =COUNTIFS(SalesData[Project_Date],">="&A19,SalesData[Project_Date],"<"&EDATE(A19,1)) -> 78 | E19: =IFERROR(AVERAGEIFS(SalesData[Profit_Margin_Pct],SalesData[Project_Date],">="&A19,SalesData[Project_Date],"<"&EDATE(A19,1)),0) -> 29.956667
A20: 45809 | B20: =SUMIFS(SalesData[Revenue],SalesData[Project_Date],">="&A20,SalesData[Project_Date],"<"&EDATE(A20,1)) -> 2628000 | C20: =SUMIFS(SalesData[Profit],SalesData[Project_Date],">="&A20,SalesData[Project_Date],"<"&EDATE(A20,1)) -> 851300 | D20: =COUNTIFS(SalesData[Project_Date],">="&A20,SalesData[Project_Date],"<"&EDATE(A20,1)) -> 60 | E20: =IFERROR(AVERAGEIFS(SalesData[Profit_Margin_Pct],SalesData[Project_Date],">="&A20,SalesData[Project_Date],"<"&EDATE(A20,1)),0) -> 30.615
A21: 45839 | B21: =SUMIFS(SalesData[Revenue],SalesData[Project_Date],">="&A21,SalesData[Project_Date],"<"&EDATE(A21,1)) -> 2943200 | C21: =SUMIFS(SalesData[Profit],SalesData[Project_Date],">="&A21,SalesData[Project_Date],"<"&EDATE(A21,1)) -> 944600 | D21: =COUNTIFS(SalesData[Project_Date],">="&A21,SalesData[Project_Date],"<"&EDATE(A21,1)) -> 64 | E21: =IFERROR(AVERAGEIFS(SalesData[Profit_Margin_Pct],SalesData[Project_Date],">="&A21,SalesData[Project_Date],"<"&EDATE(A21,1)),0) -> 32.019531
A22: 45870 | B22: =SUMIFS(SalesData[Revenue],SalesData[Project_Date],">="&A22,SalesData[Project_Date],"<"&EDATE(A22,1)) -> 2273800 | C22: =SUMIFS(SalesData[Profit],SalesData[Project_Date],">="&A22,SalesData[Project_Date],"<"&EDATE(A22,1)) -> 760600 | D22: =COUNTIFS(SalesData[Project_Date],">="&A22,SalesData[Project_Date],"<"&EDATE(A22,1)) -> 50 | E22: =IFERROR(AVERAGEIFS(SalesData[Profit_Margin_Pct],SalesData[Project_Date],">="&A22,SalesData[Project_Date],"<"&EDATE(A22,1)),0) -> 32.2208
A23: 45901 | B23: =SUMIFS(SalesData[Revenue],SalesData[Project_Date],">="&A23,SalesData[Project_Date],"<"&EDATE(A23,1)) -> 2213300 | C23: =SUMIFS(SalesData[Profit],SalesData[Project_Date],">="&A23,SalesData[Project_Date],"<"&EDATE(A23,1)) -> 698200 | D23: =COUNTIFS(SalesData[Project_Date],">="&A23,SalesData[Project_Date],"<"&EDATE(A23,1)) -> 45 | E23: =IFERROR(AVERAGEIFS(SalesData[Profit_Margin_Pct],SalesData[Project_Date],">="&A23,SalesData[Project_Date],"<"&EDATE(A23,1)),0) -> 31.446
A24: 45931 | B24: =SUMIFS(SalesData[Revenue],SalesData[Project_Date],">="&A24,SalesData[Project_Date],"<"&EDATE(A24,1)) -> 3120200 | C24: =SUMIFS(SalesData[Profit],SalesData[Project_Date],">="&A24,SalesData[Project_Date],"<"&EDATE(A24,1)) -> 914300 | D24: =COUNTIFS(SalesData[Project_Date],">="&A24,SalesData[Project_Date],"<"&EDATE(A24,1)) -> 66 | E24: =IFERROR(AVERAGEIFS(SalesData[Profit_Margin_Pct],SalesData[Project_Date],">="&A24,SalesData[Project_Date],"<"&EDATE(A24,1)),0) -> 30.087121
A25: 45962 | B25: =SUMIFS(SalesData[Revenue],SalesData[Project_Date],">="&A25,SalesData[Project_Date],"<"&EDATE(A25,1)) -> 3214200 | C25: =SUMIFS(SalesData[Profit],SalesData[Project_Date],">="&A25,SalesData[Project_Date],"<"&EDATE(A25,1)) -> 1116100 | D25: =COUNTIFS(SalesData[Project_Date],">="&A25,SalesData[Project_Date],"<"&EDATE(A25,1)) -> 69 | E25: =IFERROR(AVERAGEIFS(SalesData[Profit_Margin_Pct],SalesData[Project_Date],">="&A25,SalesData[Project_Date],"<"&EDATE(A25,1)),0) -> 33.118116
A26: 45992 | B26: =SUMIFS(SalesData[Revenue],SalesData[Project_Date],">="&A26,SalesData[Project_Date],"<"&EDATE(A26,1)) -> 2786200 | C26: =SUMIFS(SalesData[Profit],SalesData[Project_Date],">="&A26,SalesData[Project_Date],"<"&EDATE(A26,1)) -> 917200 | D26: =COUNTIFS(SalesData[Project_Date],">="&A26,SalesData[Project_Date],"<"&EDATE(A26,1)) -> 69 | E26: =IFERROR(AVERAGEIFS(SalesData[Profit_Margin_Pct],SalesData[Project_Date],">="&A26,SalesData[Project_Date],"<"&EDATE(A26,1)),0) -> 33.065362
... A38: 46357 | B38: =SUMIFS(SalesData[Revenue],SalesData[Project_Date],">="&A38,SalesData[Project_Date],"<"&EDATE(A38,1)) -> 3717700 | C38: =SUMIFS(SalesData[Profit],SalesData[Project_Date],">="&A38,SalesData[Project_Date],"<"&EDATE(A38,1)) -> 1151500 | D38: =COUNTIFS(SalesData[Project_Date],">="&A38,SalesData[Project_Date],"<"&EDATE(A38,1)) -> 77 | E38: =IFERROR(AVERAGEIFS(SalesData[Profit_Margin_Pct],SalesData[Project_Date],">="&A38,SalesData[Project_Date],"<"&EDATE(A38,1)),0) -> 30.094675
A40: SERVICE PERFORMANCE
A41: Service | B41: Revenue | C41: Profit | D41: Projects | E41: Avg Margin | F41: Revenue Share
A42: SEO | B42: =SUMIF(SalesData[Service],A42,SalesData[Revenue]) -> 8439000 | C42: =SUMIF(SalesData[Service],A42,SalesData[Profit]) -> 2754600 | D42: =COUNTIF(SalesData[Service],A42) -> 170 | E42: =IFERROR(AVERAGEIF(SalesData[Service],A42,SalesData[Profit_Margin_Pct]),0) -> 32.063 | F42: =IFERROR(B42/$B$4,0) -> 0.12076883
A43: Social Media Marketing | B43: =SUMIF(SalesData[Service],A43,SalesData[Revenue]) -> 8645500 | C43: =SUMIF(SalesData[Service],A43,SalesData[Profit]) -> 2735400 | D43: =COUNTIF(SalesData[Service],A43) -> 188 | E43: =IFERROR(AVERAGEIF(SalesData[Service],A43,SalesData[Profit_Margin_Pct]),0) -> 31.681755 | F43: =IFERROR(B43/$B$4,0) -> 0.12372401
A44: Web Design | B44: =SUMIF(SalesData[Service],A44,SalesData[Revenue]) -> 8576500 | C44: =SUMIF(SalesData[Service],A44,SalesData[Profit]) -> 2898700 | D44: =COUNTIF(SalesData[Service],A44) -> 174 | E44: =IFERROR(AVERAGEIF(SalesData[Service],A44,SalesData[Profit_Margin_Pct]),0) -> 32.972759 | F44: =IFERROR(B44/$B$4,0) -> 0.12273657
A45: Web Development | B45: =SUMIF(SalesData[Service],A45,SalesData[Revenue]) -> 9287200 | C45: =SUMIF(SalesData[Service],A45,SalesData[Profit]) -> 3033500 | D45: =COUNTIF(SalesData[Service],A45) -> 202 | E45: =IFERROR(AVERAGEIF(SalesData[Service],A45,SalesData[Profit_Margin_Pct]),0) -> 32.251584 | F45: =IFERROR(B45/$B$4,0) -> 0.13290725
A46: Content Marketing | B46: =SUMIF(SalesData[Service],A46,SalesData[Revenue]) -> 8179100 | C46: =SUMIF(SalesData[Service],A46,SalesData[Profit]) -> 2639800 | D46: =COUNTIF(SalesData[Service],A46) -> 186 | E46: =IFERROR(AVERAGEIF(SalesData[Service],A46,SalesData[Profit_Margin_Pct]),0) -> 31.601129 | F46: =IFERROR(B46/$B$4,0) -> 0.11704946
A47: PPC | B47: =SUMIF(SalesData[Service],A47,SalesData[Revenue]) -> 8826000 | C47: =SUMIF(SalesData[Service],A47,SalesData[Profit]) -> 2830200 | D47: =COUNTIF(SalesData[Service],A47) -> 188 | E47: =IFERROR(AVERAGEIF(SalesData[Service],A47,SalesData[Profit_Margin_Pct]),0) -> 31.170053 | F47: =IFERROR(B47/$B$4,0) -> 0.12630711
A48: Online Reputation Management | B48: =SUMIF(SalesData[Service],A48,SalesData[Revenue]) -> 8592300 | C48: =SUMIF(SalesData[Service],A48,SalesData[Profit]) -> 2910100 | D48: =COUNTIF(SalesData[Service],A48) -> 184 | E48: =IFERROR(AVERAGEIF(SalesData[Service],A48,SalesData[Profit_Margin_Pct]),0) -> 33.065109 | F48: =IFERROR(B48/$B$4,0) -> 0.12296268
A49: Mobile App Development | B49: =SUMIF(SalesData[Service],A49,SalesData[Revenue]) -> 9331700 | C49: =SUMIF(SalesData[Service],A49,SalesData[Profit]) -> 2932000 | D49: =COUNTIF(SalesData[Service],A49) -> 209 | E49: =IFERROR(AVERAGEIF(SalesData[Service],A49,SalesData[Profit_Margin_Pct]),0) -> 30.218134 | F49: =IFERROR(B49/$B$4,0) -> 0.13354408
A52: REGIONAL PERFORMANCE
A53: Region | B53: Revenue | C53: Profit | D53: Projects | E53: Avg Margin
A54: Mumbai | B54: =SUMIF(SalesData[Region],A54,SalesData[Revenue]) -> 7313200 | C54: =SUMIF(SalesData[Region],A54,SalesData[Profit]) -> 2329000 | D54: =COUNTIF(SalesData[Region],A54) -> 158 | E54: =IFERROR(AVERAGEIF(SalesData[Region],A54,SalesData[Profit_Margin_Pct]),0) -> 31.62538
A55: Delhi Ncr | B55: =SUMIF(SalesData[Region],A55,SalesData[Revenue]) -> 8293700 | C55: =SUMIF(SalesData[Region],A55,SalesData[Profit]) -> 2646400 | D55: =COUNTIF(SalesData[Region],A55) -> 194 | E55: =IFERROR(AVERAGEIF(SalesData[Region],A55,SalesData[Profit_Margin_Pct]),0) -> 31.055773
A56: Bengaluru | B56: =SUMIF(SalesData[Region],A56,SalesData[Revenue]) -> 10792000 | C56: =SUMIF(SalesData[Region],A56,SalesData[Profit]) -> 3605300 | D56: =COUNTIF(SalesData[Region],A56) -> 212 | E56: =IFERROR(AVERAGEIF(SalesData[Region],A56,SalesData[Profit_Margin_Pct]),0) -> 32.613538
A57: Pune | B57: =SUMIF(SalesData[Region],A57,SalesData[Revenue]) -> 8568000 | C57: =SUMIF(SalesData[Region],A57,SalesData[Profit]) -> 2745200 | D57: =COUNTIF(SalesData[Region],A57) -> 180 | E57: =IFERROR(AVERAGEIF(SalesData[Region],A57,SalesData[Profit_Margin_Pct]),0) -> 31.332167
...

Sheet Beginner_Dashboard
A1: DASHBOARD
A2: Business Performance Dashboard – Beginner Level
A4: Total Revenue | D4: Total Profit | G4: Projects | J4: Clients
A5: =Beginner_Analysis!B4 -> 69877300 | D5: =Beginner_Analysis!B5 -> 22734300 | G5: =Beginner_Analysis!B6 -> 1501 | J5: =Beginner_Analysis!B7 -> 405
A7: Avg Project Value | D7: Avg Margin | G7: Avg Rating
A8: =Beginner_Analysis!B8 -> 50758.095 | D8: =Beginner_Analysis!B9 -> 31.842978 | G8: =Beginner_Analysis!B10 -> 4.0634459
A11: Month | B11: Revenue | C11: Profit | F11: Service | G11: Revenue | H11: Profit
A12: =Beginner_Analysis!A15 -> 45658 | B12: =Beginner_Analysis!B15 -> 2823200 | C12: =Beginner_Analysis!C15 -> 901400 | F12: =Beginner_Analysis!A42 -> SEO | G12: =Beginner_Analysis!B42 -> 8439000 | H12: =Beginner_Analysis!C42 -> 2754600
A13: =Beginner_Analysis!A16 -> 45689 | B13: =Beginner_Analysis!B16 -> 2622300 | C13: =Beginner_Analysis!C16 -> 847800 | F13: =Beginner_Analysis!A43 -> Social Media Marketing | G13: =Beginner_Analysis!B43 -> 8645500 | H13: =Beginner_Analysis!C43 -> 2735400
A14: =Beginner_Analysis!A17 -> 45717 | B14: =Beginner_Analysis!B17 -> 2921200 | C14: =Beginner_Analysis!C17 -> 957800 | F14: =Beginner_Analysis!A44 -> Web Design | G14: =Beginner_Analysis!B44 -> 8576500 | H14: =Beginner_Analysis!C44 -> 2898700
A15: =Beginner_Analysis!A18 -> 45748 | B15: =Beginner_Analysis!B18 -> 3502500 | C15: =Beginner_Analysis!C18 -> 1139800 | F15: =Beginner_Analysis!A45 -> Web Development | G15: =Beginner_Analysis!B45 -> 9287200 | H15: =Beginner_Analysis!C45 -> 3033500
A16: =Beginner_Analysis!A19 -> 45778 | B16: =Beginner_Analysis!B19 -> 3582200 | C16: =Beginner_Analysis!C19 -> 1056200 | F16: =Beginner_Analysis!A46 -> Content Marketing | G16: =Beginner_Analysis!B46 -> 8179100 | H16: =Beginner_Analysis!C46 -> 2639800
A17: =Beginner_Analysis!A20 -> 45809 | B17: =Beginner_Analysis!B20 -> 2628000 | C17: =Beginner_Analysis!C20 -> 851300 | F17: =Beginner_Analysis!A47 -> PPC | G17: =Beginner_Analysis!B47 -> 8826000 | H17: =Beginner_Analysis!C47 -> 2830200
A18: =Beginner_Analysis!A21 -> 45839 | B18: =Beginner_Analysis!B21 -> 2943200 | C18: =Beginner_Analysis!C21 -> 944600 | F18: =Beginner_Analysis!A48 -> Online Reputation Management | G18: =Beginner_Analysis!B48 -> 8592300 | H18: =Beginner_Analysis!C48 -> 2910100
A19: =Beginner_Analysis!A22 -> 45870 | B19: =Beginner_Analysis!B22 -> 2273800 | C19: =Beginner_Analysis!C22 -> 760600 | F19: =Beginner_Analysis!A49 -> Mobile App Development | G19: =Beginner_Analysis!B49 -> 9331700 | H19: =Beginner_Analysis!C49 -> 2932000
A20: =Beginner_Analysis!A23 -> 45901 | B20: =Beginner_Analysis!B23 -> 2213300 | C20: =Beginner_Analysis!C23 -> 698200
A21: =Beginner_Analysis!A24 -> 45931 | B21: =Beginner_Analysis!B24 -> 3120200 | C21: =Beginner_Analysis!C24 -> 914300
A22: =Beginner_Analysis!A25 -> 45962 | B22: =Beginner_Analysis!B25 -> 3214200 | C22: =Beginner_Analysis!C25 -> 1116100
A23: =Beginner_Analysis!A26 -> 45992 | B23: =Beginner_Analysis!B26 -> 2786200 | C23: =Beginner_Analysis!C26 -> 917200
A24: =Beginner_Analysis!A27 -> 46023 | B24: =Beginner_Analysis!B27 -> 2483900 | C24: =Beginner_Analysis!C27 -> 854600
A25: =Beginner_Analysis!A28 -> 46054 | B25: =Beginner_Analysis!B28 -> 3022400 | C25: =Beginner_Analysis!C28 -> 942000
A26: =Beginner_Analysis!A29 -> 46082 | B26: =Beginner_Analysis!B29 -> 2271300 | C26: =Beginner_Analysis!C29 -> 753900
A27: =Beginner_Analysis!A30 -> 46113 | B27: =Beginner_Analysis!B30 -> 3050000 | C27: =Beginner_Analysis!C30 -> 1094200
A28: =Beginner_Analysis!A31 -> 46143 | B28: =Beginner_Analysis!B31 -> 2620300 | C28: =Beginner_Analysis!C31 -> 905600
A29: =Beginner_Analysis!A32 -> 46174 | B29: =Beginner_Analysis!B32 -> 2657700 | C29: =Beginner_Analysis!C32 -> 766400
A30: =Beginner_Analysis!A33 -> 46204 | B30: =Beginner_Analysis!B33 -> 3359200 | C30: =Beginner_Analysis!C33 -> 1061300
A31: =Beginner_Analysis!A34 -> 46235 | B31: =Beginner_Analysis!B34 -> 3319500 | C31: =Beginner_Analysis!C34 -> 1076900
... A35: =Beginner_Analysis!A38 -> 46357 | B35: =Beginner_Analysis!B38 -> 3717700 | C35: =Beginner_Analysis!C38 -> 1151500

Sheet Intermediate_Analysis
A1: INTERMEDIATE – CUSTOMER, REVENUE & BUSINESS ANALYSIS
A3: Metric | B3: Value
A4: Unique Clients | B4: =SUMPRODUCT(1/COUNTIF(SalesData[Client_ID],SalesData[Client_ID])) -> 405
A5: Repeat Clients | B5: =SUMPRODUCT((COUNTIF(SalesData[Client_ID],SalesData[Client_ID])>1)/COUNTIF(SalesData[Client_ID],SalesData[Client_ID])) -> 358
A6: Repeat Client % | B6: =IFERROR(B5/B4,0) -> 0.88395062
A7: New Client Revenue | B7: =SUMIF(SalesData[Client_Type],"New",SalesData[Revenue]) -> 43076600
A8: Returning Client Revenue | B8: =SUMIF(SalesData[Client_Type],"Returning",SalesData[Revenue]) -> 26800700
A9: Average Revenue per Client | B9: =IFERROR(SUM(SalesData[Revenue])/B4,0) -> 172536.54
A13: SERVICE PROFITABILITY
A14: Service | B14: Revenue | C14: Profit | D14: Projects | E14: Avg Margin | F14: Revenue Share
A15: SEO | B15: =SUMIF(SalesData[Service],A15,SalesData[Revenue]) -> 8439000 | C15: =SUMIF(SalesData[Service],A15,SalesData[Profit]) -> 2754600 | D15: =COUNTIF(SalesData[Service],A15) -> 170 | E15: =IFERROR(AVERAGEIF(SalesData[Service],A15,SalesData[Profit_Margin_Pct]),0) -> 32.063 | F15: =IFERROR(B15/SUM(SalesData[Revenue]),0) -> 0.12076883
A16: Social Media Marketing | B16: =SUMIF(SalesData[Service],A16,SalesData[Revenue]) -> 8645500 | C16: =SUMIF(SalesData[Service],A16,SalesData[Profit]) -> 2735400 | D16: =COUNTIF(SalesData[Service],A16) -> 188 | E16: =IFERROR(AVERAGEIF(SalesData[Service],A16,SalesData[Profit_Margin_Pct]),0) -> 31.681755 | F16: =IFERROR(B16/SUM(SalesData[Revenue]),0) -> 0.12372401
A17: Web Design | B17: =SUMIF(SalesData[Service],A17,SalesData[Revenue]) -> 8576500 | C17: =SUMIF(SalesData[Service],A17,SalesData[Profit]) -> 2898700 | D17: =COUNTIF(SalesData[Service],A17) -> 174 | E17: =IFERROR(AVERAGEIF(SalesData[Service],A17,SalesData[Profit_Margin_Pct]),0) -> 32.972759 | F17: =IFERROR(B17/SUM(SalesData[Revenue]),0) -> 0.12273657
A18: Web Development | B18: =SUMIF(SalesData[Service],A18,SalesData[Revenue]) -> 9287200 | C18: =SUMIF(SalesData[Service],A18,SalesData[Profit]) -> 3033500 | D18: =COUNTIF(SalesData[Service],A18) -> 202 | E18: =IFERROR(AVERAGEIF(SalesData[Service],A18,SalesData[Profit_Margin_Pct]),0) -> 32.251584 | F18: =IFERROR(B18/SUM(SalesData[Revenue]),0) -> 0.13290725
A19: Content Marketing | B19: =SUMIF(SalesData[Service],A19,SalesData[Revenue]) -> 8179100 | C19: =SUMIF(SalesData[Service],A19,SalesData[Profit]) -> 2639800 | D19: =COUNTIF(SalesData[Service],A19) -> 186 | E19: =IFERROR(AVERAGEIF(SalesData[Service],A19,SalesData[Profit_Margin_Pct]),0) -> 31.601129 | F19: =IFERROR(B19/SUM(SalesData[Revenue]),0) -> 0.11704946
A20: PPC | B20: =SUMIF(SalesData[Service],A20,SalesData[Revenue]) -> 8826000 | C20: =SUMIF(SalesData[Service],A20,SalesData[Profit]) -> 2830200 | D20: =COUNTIF(SalesData[Service],A20) -> 188 | E20: =IFERROR(AVERAGEIF(SalesData[Service],A20,SalesData[Profit_Margin_Pct]),0) -> 31.170053 | F20: =IFERROR(B20/SUM(SalesData[Revenue]),0) -> 0.12630711
A21: Online Reputation Management | B21: =SUMIF(SalesData[Service],A21,SalesData[Revenue]) -> 8592300 | C21: =SUMIF(SalesData[Service],A21,SalesData[Profit]) -> 2910100 | D21: =COUNTIF(SalesData[Service],A21) -> 184 | E21: =IFERROR(AVERAGEIF(SalesData[Service],A21,SalesData[Profit_Margin_Pct]),0) -> 33.065109 | F21: =IFERROR(B21/SUM(SalesData[Revenue]),0) -> 0.12296268
A22: Mobile App Development | B22: =SUMIF(SalesData[Service],A22,SalesData[Revenue]) -> 9331700 | C22: =SUMIF(SalesData[Service],A22,SalesData[Profit]) -> 2932000 | D22: =COUNTIF(SalesData[Service],A22) -> 209 | E22: =IFERROR(AVERAGEIF(SalesData[Service],A22,SalesData[Profit_Margin_Pct]),0) -> 30.218134 | F22: =IFERROR(B22/SUM(SalesData[Revenue]),0) -> 0.13354408
A26: CUSTOMER RANKING
A27: Rank | B27: Client ID | C27: Projects | D27: Revenue | E27: Profit | F27: Avg Rating
A28: 1 | B28: C0050 | C28: =COUNTIF(SalesData[Client_ID],B28) -> 9 | D28: =SUMIF(SalesData[Client_ID],B28,SalesData[Revenue]) -> 528400 | E28: =SUMIF(SalesData[Client_ID],B28,SalesData[Profit]) -> 166900 | F28: =IFERROR(AVERAGEIF(SalesData[Client_ID],B28,SalesData[Customer_Rating]),0) -> 4.5888889
A29: 2 | B29: C0344 | C29: =COUNTIF(SalesData[Client_ID],B29) -> 9 | D29: =SUMIF(SalesData[Client_ID],B29,SalesData[Revenue]) -> 509600 | E29: =SUMIF(SalesData[Client_ID],B29,SalesData[Profit]) -> 178900 | F29: =IFERROR(AVERAGEIF(SalesData[Client_ID],B29,SalesData[Customer_Rating]),0) -> 3.9333333
A30: 3 | B30: C0086 | C30: =COUNTIF(SalesData[Client_ID],B30) -> 9 | D30: =SUMIF(SalesData[Client_ID],B30,SalesData[Revenue]) -> 445000 | E30: =SUMIF(SalesData[Client_ID],B30,SalesData[Profit]) -> 120100 | F30: =IFERROR(AVERAGEIF(SalesData[Client_ID],B30,SalesData[Customer_Rating]),0) -> 3.7555556
A31: 4 | B31: C0241 | C31: =COUNTIF(SalesData[Client_ID],B31) -> 8 | D31: =SUMIF(SalesData[Client_ID],B31,SalesData[Revenue]) -> 440400 | E31: =SUMIF(SalesData[Client_ID],B31,SalesData[Profit]) -> 107700 | F31: =IFERROR(AVERAGEIF(SalesData[Client_ID],B31,SalesData[Customer_Rating]),0) -> 3.975
A32: 5 | B32: C0047 | C32: =COUNTIF(SalesData[Client_ID],B32) -> 8 | D32: =SUMIF(SalesData[Client_ID],B32,SalesData[Revenue]) -> 432300 | E32: =SUMIF(SalesData[Client_ID],B32,SalesData[Profit]) -> 118800 | F32: =IFERROR(AVERAGEIF(SalesData[Client_ID],B32,SalesData[Customer_Rating]),0) -> 3.9125
A33: 6 | B33: C0089 | C33: =COUNTIF(SalesData[Client_ID],B33) -> 5 | D33: =SUMIF(SalesData[Client_ID],B33,SalesData[Revenue]) -> 407000 | E33: =SUMIF(SalesData[Client_ID],B33,SalesData[Profit]) -> 176800 | F33: =IFERROR(AVERAGEIF(SalesData[Client_ID],B33,SalesData[Customer_Rating]),0) -> 4.4
A34: 7 | B34: C0203 | C34: =COUNTIF(SalesData[Client_ID],B34) -> 7 | D34: =SUMIF(SalesData[Client_ID],B34,SalesData[Revenue]) -> 383000 | E34: =SUMIF(SalesData[Client_ID],B34,SalesData[Profit]) -> 120000 | F34: =IFERROR(AVERAGEIF(SalesData[Client_ID],B34,SalesData[Customer_Rating]),0) -> 4.2571429
A35: 8 | B35: C0204 | C35: =COUNTIF(SalesData[Client_ID],B35) -> 8 | D35: =SUMIF(SalesData[Client_ID],B35,SalesData[Revenue]) -> 378200 | E35: =SUMIF(SalesData[Client_ID],B35,SalesData[Profit]) -> 106300 | F35: =IFERROR(AVERAGEIF(SalesData[Client_ID],B35,SalesData[Customer_Rating]),0) -> 4.1375
A36: 9 | B36: C0322 | C36: =COUNTIF(SalesData[Client_ID],B36) -> 7 | D36: =SUMIF(SalesData[Client_ID],B36,SalesData[Revenue]) -> 376900 | E36: =SUMIF(SalesData[Client_ID],B36,SalesData[Profit]) -> 122100 | F36: =IFERROR(AVERAGEIF(SalesData[Client_ID],B36,SalesData[Customer_Rating]),0) -> 3.7571429
A37: 10 | B37: C0218 | C37: =COUNTIF(SalesData[Client_ID],B37) -> 6 | D37: =SUMIF(SalesData[Client_ID],B37,SalesData[Revenue]) -> 374200 | E37: =SUMIF(SalesData[Client_ID],B37,SalesData[Profit]) -> 123800 | F37: =IFERROR(AVERAGEIF(SalesData[Client_ID],B37,SalesData[Customer_Rating]),0) -> 3.8666667
A38: 11 | B38: C0348 | C38: =COUNTIF(SalesData[Client_ID],B38) -> 7 | D38: =SUMIF(SalesData[Client_ID],B38,SalesData[Revenue]) -> 372700 | E38: =SUMIF(SalesData[Client_ID],B38,SalesData[Profit]) -> 93700 | F38: =IFERROR(AVERAGEIF(SalesData[Client_ID],B38,SalesData[Customer_Rating]),0) -> 4.3
A39: 12 | B39: C0403 | C39: =COUNTIF(SalesData[Client_ID],B39) -> 6 | D39: =SUMIF(SalesData[Client_ID],B39,SalesData[Revenue]) -> 365700 | E39: =SUMIF(SalesData[Client_ID],B39,SalesData[Profit]) -> 102000 | F39: =IFERROR(AVERAGEIF(SalesData[Client_ID],B39,SalesData[Customer_Rating]),0) -> 4.2833333
... A42: 15 | B42: C0233 | C42: =COUNTIF(SalesData[Client_ID],B42) -> 7 | D42: =SUMIF(SalesData[Client_ID],B42,SalesData[Revenue]) -> 362700 | E42: =SUMIF(SalesData[Client_ID],B42,SalesData[Profit]) -> 116400 | F42: =IFERROR(AVERAGEIF(SalesData[Client_ID],B42,SalesData[Customer_Rating]),0) -> 3.8
A45: MARKETING / LEAD SOURCE PERFORMANCE
A46: Lead Source | B46: Revenue | C46: Profit | D46: Projects | E46: Marketing Spend | F46: ROI
A47: Direct | B47: =SUMIF(SalesData[Lead_Source],A47,SalesData[Revenue]) -> 13274500 | C47: =SUMIF(SalesData[Lead_Source],A47,SalesData[Profit]) -> 4361600 | D47: =COUNTIF(SalesData[Lead_Source],A47) -> 268 | E47: =SUMIF(SalesData[Lead_Source],A47,SalesData[Marketing_Spend]) -> 1428400 | F47: =IFERROR((B47-E47)/E47,0) -> 8.2932652
A48: Email Campaign | B48: =SUMIF(SalesData[Lead_Source],A48,SalesData[Revenue]) -> 10926800 | C48: =SUMIF(SalesData[Lead_Source],A48,SalesData[Profit]) -> 3566100 | D48: =COUNTIF(SalesData[Lead_Source],A48) -> 246 | E48: =SUMIF(SalesData[Lead_Source],A48,SalesData[Marketing_Spend]) -> 1151100 | F48: =IFERROR((B48-E48)/E48,0) -> 8.4924854
A49: Google | B49: =SUMIF(SalesData[Lead_Source],A49,SalesData[Revenue]) -> 11135800 | C49: =SUMIF(SalesData[Lead_Source],A49,SalesData[Profit]) -> 3613100 | D49: =COUNTIF(SalesData[Lead_Source],A49) -> 232 | E49: =SUMIF(SalesData[Lead_Source],A49,SalesData[Marketing_Spend]) -> 1206300 | F49: =IFERROR((B49-E49)/E49,0) -> 8.2313686
A50: Partner | B50: =SUMIF(SalesData[Lead_Source],A50,SalesData[Revenue]) -> 11973600 | C50: =SUMIF(SalesData[Lead_Source],A50,SalesData[Profit]) -> 3837800 | D50: =COUNTIF(SalesData[Lead_Source],A50) -> 262 | E50: =SUMIF(SalesData[Lead_Source],A50,SalesData[Marketing_Spend]) -> 1352800 | F50: =IFERROR((B50-E50)/E50,0) -> 7.8509758
A51: Referral | B51: =SUMIF(SalesData[Lead_Source],A51,SalesData[Revenue]) -> 10488100 | C51: =SUMIF(SalesData[Lead_Source],A51,SalesData[Profit]) -> 3312400 | D51: =COUNTIF(SalesData[Lead_Source],A51) -> 233 | E51: =SUMIF(SalesData[Lead_Source],A51,SalesData[Marketing_Spend]) -> 1170800 | F51: =IFERROR((B51-E51)/E51,0) -> 7.9580629
...

Sheet Intermediate_Insights
A4: EVIDENCE-BACKED INTERMEDIATE FINDINGS
A6: 2. Mobile App Development leads revenue at ₹9,331,700, while Web Development leads total profit at ₹3,033,500.
A7: 3. 358 of 405 clients have multiple projects (88.4%), providing a measurable repeat-business segment.
A8: 4. Direct is the largest lead source by revenue; its marketing spend should be considered alongside revenue when evaluating performance.
A9: 5. Bengaluru is the highest-revenue region; regional performance should be compared using both revenue and margin.
A10: 6. Education is the largest industry by revenue and is a useful segment for deeper customer and service analysis.
A13: DECISION-ORIENTED RECOMMENDATIONS
A15: 2. Compare service volume with profit margin before prioritizing growth.
A16: 3. Use repeat-client behavior to identify services that can support retention and follow-up opportunities.
A17: 4. Evaluate lead sources using both revenue and marketing spend rather than project count alone.
A18: 5. Investigate high-revenue regions or industries where margins are comparatively weaker.
A19: 6. Use the advanced Power BI dashboard to filter these findings by time, service, region, industry and client type.
